[93mWARNING [0m:   DEPRECATED FEATURE: flwr.client.start_numpy_client() is deprecated.
	Instead, use `flwr.client.start_client()` by ensuring you first call the `.to_client()` method as shown below:
	flwr.client.start_client(
		server_address='<IP>:<PORT>',
		client=FlowerClient().to_client(), # <-- where FlowerClient is of type flwr.client.NumPyClient object
	)
	Using `start_numpy_client()` is deprecated.

            This is a deprecated feature. It will be removed
            entirely in future versions of Flower.

[2025-09-29 17:25:09,543][flwr][WARNING] - DEPRECATED FEATURE: flwr.client.start_numpy_client() is deprecated.
	Instead, use `flwr.client.start_client()` by ensuring you first call the `.to_client()` method as shown below:
	flwr.client.start_client(
		server_address='<IP>:<PORT>',
		client=FlowerClient().to_client(), # <-- where FlowerClient is of type flwr.client.NumPyClient object
	)
	Using `start_numpy_client()` is deprecated.

            This is a deprecated feature. It will be removed
            entirely in future versions of Flower.

[93mWARNING [0m:   DEPRECATED FEATURE: flwr.client.start_client() is deprecated.
	Instead, use the `flower-supernode` CLI command to start a SuperNode as shown below:

		$ flower-supernode --insecure --superlink='<IP>:<PORT>'

	To view all available options, run:

		$ flower-supernode --help

	Using `start_client()` is deprecated.

            This is a deprecated feature. It will be removed
            entirely in future versions of Flower.

[2025-09-29 17:25:09,545][flwr][WARNING] - DEPRECATED FEATURE: flwr.client.start_client() is deprecated.
	Instead, use the `flower-supernode` CLI command to start a SuperNode as shown below:

		$ flower-supernode --insecure --superlink='<IP>:<PORT>'

	To view all available options, run:

		$ flower-supernode --help

	Using `start_client()` is deprecated.

            This is a deprecated feature. It will be removed
            entirely in future versions of Flower.

[2025-09-29 17:25:09,574][flwr][DEBUG] - Opened insecure gRPC connection (no certificates were passed)
[2025-09-29 17:25:09,577][flwr][DEBUG] - ChannelConnectivity.IDLE
[2025-09-29 17:25:09,578][flwr][DEBUG] - ChannelConnectivity.CONNECTING
[2025-09-29 17:25:09,585][flwr][DEBUG] - ChannelConnectivity.READY
[32mINFO[0m:     Shutting down
[32mINFO[0m:     Waiting for background tasks to complete. (CTRL+C to force quit)
[32mINFO[0m:     Finished server process [[36m609037[0m]
[31mERROR[0m:    Exception in ASGI application
Traceback (most recent call last):
  File "/home/ccl/anaconda3/envs/rrfedops/lib/python3.9/asyncio/runners.py", line 44, in run
    return loop.run_until_complete(main)
  File "uvloop/loop.pyx", line 1512, in uvloop.loop.Loop.run_until_complete
  File "uvloop/loop.pyx", line 1505, in uvloop.loop.Loop.run_until_complete
  File "uvloop/loop.pyx", line 1379, in uvloop.loop.Loop.run_forever
  File "uvloop/loop.pyx", line 557, in uvloop.loop.Loop._run
  File "uvloop/loop.pyx", line 476, in uvloop.loop.Loop._on_idle
  File "uvloop/cbhandles.pyx", line 83, in uvloop.loop.Handle._run
  File "uvloop/cbhandles.pyx", line 63, in uvloop.loop.Handle._run
  File "/home/ccl/anaconda3/envs/rrfedops/lib/python3.9/site-packages/uvicorn/server.py", line 70, in serve
    await self._serve(sockets)
  File "/home/ccl/anaconda3/envs/rrfedops/lib/python3.9/contextlib.py", line 126, in __exit__
    next(self.gen)
  File "/home/ccl/anaconda3/envs/rrfedops/lib/python3.9/site-packages/uvicorn/server.py", line 330, in capture_signals
    signal.raise_signal(captured_signal)
KeyboardInterrupt

During handling of the above exception, another exception occurred:

Traceback (most recent call last):
  File "/home/ccl/anaconda3/envs/rrfedops/lib/python3.9/site-packages/uvicorn/protocols/http/httptools_impl.py", line 409, in run_asgi
    result = await app(  # type: ignore[func-returns-value]
  File "/home/ccl/anaconda3/envs/rrfedops/lib/python3.9/site-packages/uvicorn/middleware/proxy_headers.py", line 60, in __call__
    return await self.app(scope, receive, send)
  File "/home/ccl/anaconda3/envs/rrfedops/lib/python3.9/site-packages/fastapi/applications.py", line 1054, in __call__
    await super().__call__(scope, receive, send)
  File "/home/ccl/anaconda3/envs/rrfedops/lib/python3.9/site-packages/starlette/applications.py", line 112, in __call__
    await self.middleware_stack(scope, receive, send)
  File "/home/ccl/anaconda3/envs/rrfedops/lib/python3.9/site-packages/starlette/middleware/errors.py", line 165, in __call__
    await self.app(scope, receive, _send)
  File "/home/ccl/anaconda3/envs/rrfedops/lib/python3.9/site-packages/starlette/middleware/exceptions.py", line 62, in __call__
    await wrap_app_handling_exceptions(self.app, conn)(scope, receive, send)
  File "/home/ccl/anaconda3/envs/rrfedops/lib/python3.9/site-packages/starlette/_exception_handler.py", line 42, in wrapped_app
    await app(scope, receive, sender)
  File "/home/ccl/anaconda3/envs/rrfedops/lib/python3.9/site-packages/starlette/routing.py", line 714, in __call__
    await self.middleware_stack(scope, receive, send)
  File "/home/ccl/anaconda3/envs/rrfedops/lib/python3.9/site-packages/starlette/routing.py", line 734, in app
    await route.handle(scope, receive, send)
  File "/home/ccl/anaconda3/envs/rrfedops/lib/python3.9/site-packages/starlette/routing.py", line 288, in handle
    await self.app(scope, receive, send)
  File "/home/ccl/anaconda3/envs/rrfedops/lib/python3.9/site-packages/starlette/routing.py", line 76, in app
    await wrap_app_handling_exceptions(app, request)(scope, receive, send)
  File "/home/ccl/anaconda3/envs/rrfedops/lib/python3.9/site-packages/starlette/_exception_handler.py", line 42, in wrapped_app
    await app(scope, receive, sender)
  File "/home/ccl/anaconda3/envs/rrfedops/lib/python3.9/site-packages/starlette/routing.py", line 74, in app
    await response(scope, receive, send)
  File "/home/ccl/anaconda3/envs/rrfedops/lib/python3.9/site-packages/starlette/responses.py", line 160, in __call__
    await self.background()
  File "/home/ccl/anaconda3/envs/rrfedops/lib/python3.9/site-packages/starlette/background.py", line 41, in __call__
    await task()
  File "/home/ccl/anaconda3/envs/rrfedops/lib/python3.9/site-packages/starlette/background.py", line 26, in __call__
    await self.func(*self.args, **self.kwargs)
  File "/home/ccl/Desktop/RR/FedOps2/fedopstest/app.py", line 124, in fl_client_start
    await loop.run_in_executor(None, client_start)
asyncio.exceptions.CancelledError
[31mERROR[0m:    Traceback (most recent call last):
  File "/home/ccl/anaconda3/envs/rrfedops/lib/python3.9/asyncio/runners.py", line 44, in run
    return loop.run_until_complete(main)
  File "uvloop/loop.pyx", line 1512, in uvloop.loop.Loop.run_until_complete
  File "uvloop/loop.pyx", line 1505, in uvloop.loop.Loop.run_until_complete
  File "uvloop/loop.pyx", line 1379, in uvloop.loop.Loop.run_forever
  File "uvloop/loop.pyx", line 557, in uvloop.loop.Loop._run
  File "uvloop/loop.pyx", line 476, in uvloop.loop.Loop._on_idle
  File "uvloop/cbhandles.pyx", line 83, in uvloop.loop.Handle._run
  File "uvloop/cbhandles.pyx", line 63, in uvloop.loop.Handle._run
  File "/home/ccl/anaconda3/envs/rrfedops/lib/python3.9/site-packages/uvicorn/server.py", line 70, in serve
    await self._serve(sockets)
  File "/home/ccl/anaconda3/envs/rrfedops/lib/python3.9/contextlib.py", line 126, in __exit__
    next(self.gen)
  File "/home/ccl/anaconda3/envs/rrfedops/lib/python3.9/site-packages/uvicorn/server.py", line 330, in capture_signals
    signal.raise_signal(captured_signal)
KeyboardInterrupt

During handling of the above exception, another exception occurred:

Traceback (most recent call last):
  File "/home/ccl/anaconda3/envs/rrfedops/lib/python3.9/site-packages/starlette/routing.py", line 699, in lifespan
    await receive()
  File "/home/ccl/anaconda3/envs/rrfedops/lib/python3.9/site-packages/uvicorn/lifespan/on.py", line 137, in receive
    return await self.receive_queue.get()
  File "/home/ccl/anaconda3/envs/rrfedops/lib/python3.9/asyncio/queues.py", line 166, in get
    await getter
asyncio.exceptions.CancelledError

Error executing job with overrides: []
Traceback (most recent call last):
  File "/home/ccl/anaconda3/envs/rrfedops/lib/python3.9/site-packages/urllib3/connection.py", line 174, in _new_conn
    conn = connection.create_connection(
  File "/home/ccl/anaconda3/envs/rrfedops/lib/python3.9/site-packages/urllib3/util/connection.py", line 95, in create_connection
    raise err
  File "/home/ccl/anaconda3/envs/rrfedops/lib/python3.9/site-packages/urllib3/util/connection.py", line 85, in create_connection
    sock.connect(sa)
ConnectionRefusedError: [Errno 111] Connection refused

During handling of the above exception, another exception occurred:

Traceback (most recent call last):
  File "/home/ccl/anaconda3/envs/rrfedops/lib/python3.9/site-packages/urllib3/connectionpool.py", line 716, in urlopen
    httplib_response = self._make_request(
  File "/home/ccl/anaconda3/envs/rrfedops/lib/python3.9/site-packages/urllib3/connectionpool.py", line 416, in _make_request
    conn.request(method, url, **httplib_request_kw)
  File "/home/ccl/anaconda3/envs/rrfedops/lib/python3.9/site-packages/urllib3/connection.py", line 244, in request
    super(HTTPConnection, self).request(method, url, body=body, headers=headers)
  File "/home/ccl/anaconda3/envs/rrfedops/lib/python3.9/http/client.py", line 1285, in request
    self._send_request(method, url, body, headers, encode_chunked)
  File "/home/ccl/anaconda3/envs/rrfedops/lib/python3.9/http/client.py", line 1331, in _send_request
    self.endheaders(body, encode_chunked=encode_chunked)
  File "/home/ccl/anaconda3/envs/rrfedops/lib/python3.9/http/client.py", line 1280, in endheaders
    self._send_output(message_body, encode_chunked=encode_chunked)
  File "/home/ccl/anaconda3/envs/rrfedops/lib/python3.9/http/client.py", line 1040, in _send_output
    self.send(msg)
  File "/home/ccl/anaconda3/envs/rrfedops/lib/python3.9/http/client.py", line 980, in send
    self.connect()
  File "/home/ccl/anaconda3/envs/rrfedops/lib/python3.9/site-packages/urllib3/connection.py", line 205, in connect
    conn = self._new_conn()
  File "/home/ccl/anaconda3/envs/rrfedops/lib/python3.9/site-packages/urllib3/connection.py", line 186, in _new_conn
    raise NewConnectionError(
urllib3.exceptions.NewConnectionError: <urllib3.connection.HTTPConnection object at 0x7f8372c1ab80>: Failed to establish a new connection: [Errno 111] Connection refused

During handling of the above exception, another exception occurred:

Traceback (most recent call last):
  File "/home/ccl/.local/lib/python3.9/site-packages/requests/adapters.py", line 667, in send
    resp = conn.urlopen(
  File "/home/ccl/anaconda3/envs/rrfedops/lib/python3.9/site-packages/urllib3/connectionpool.py", line 802, in urlopen
    retries = retries.increment(
  File "/home/ccl/anaconda3/envs/rrfedops/lib/python3.9/site-packages/urllib3/util/retry.py", line 594, in increment
    raise MaxRetryError(_pool, url, error or ResponseError(cause))
urllib3.exceptions.MaxRetryError: HTTPConnectionPool(host='localhost', port=8004): Max retries exceeded with url: /flclient_out (Caused by NewConnectionError('<urllib3.connection.HTTPConnection object at 0x7f8372c1ab80>: Failed to establish a new connection: [Errno 111] Connection refused'))

During handling of the above exception, another exception occurred:

Traceback (most recent call last):
  File "/home/ccl/Desktop/RR/FedOps2/fedopstest/client_main.py", line 84, in main
    fl_client.start()
  File "/home/ccl/Desktop/RR/FedOps2/fedopstest/app.py", line 214, in start
    client_api.ClientMangerAPI().get_client_out()
  File "/home/ccl/Desktop/RR/FedOps2/fedopstest/client_api.py", line 36, in get_client_out
    requests.get(self.client_manager_addr + '/flclient_out')
  File "/home/ccl/.local/lib/python3.9/site-packages/requests/api.py", line 73, in get
    return request("get", url, params=params, **kwargs)
  File "/home/ccl/.local/lib/python3.9/site-packages/requests/api.py", line 59, in request
    return session.request(method=method, url=url, **kwargs)
  File "/home/ccl/.local/lib/python3.9/site-packages/requests/sessions.py", line 589, in request
    resp = self.send(prep, **send_kwargs)
  File "/home/ccl/.local/lib/python3.9/site-packages/requests/sessions.py", line 703, in send
    r = adapter.send(request, **kwargs)
  File "/home/ccl/.local/lib/python3.9/site-packages/requests/adapters.py", line 700, in send
    raise ConnectionError(e, request=request)
requests.exceptions.ConnectionError: HTTPConnectionPool(host='localhost', port=8004): Max retries exceeded with url: /flclient_out (Caused by NewConnectionError('<urllib3.connection.HTTPConnection object at 0x7f8372c1ab80>: Failed to establish a new connection: [Errno 111] Connection refused'))

Set the environment variable HYDRA_FULL_ERROR=1 for a complete stack trace.
Exception ignored in: <module 'threading' from '/home/ccl/anaconda3/envs/rrfedops/lib/python3.9/threading.py'>Exception in thread
Thread-9Traceback (most recent call last):
:
  File "/home/ccl/anaconda3/envs/rrfedops/lib/python3.9/threading.py", line 1447, in _shutdown
Traceback (most recent call last):
  File "uvloop/loop.pyx", line 3254, in uvloop.loop.Loop._do_shutdown
    atexit_call()
  File "/home/ccl/anaconda3/envs/rrfedops/lib/python3.9/concurrent/futures/thread.py", line 31, in _python_exit
  File "uvloop/loop.pyx", line 1290, in uvloop.loop.Loop.call_soon_threadsafe
    t.join()  File "uvloop/loop.pyx", line 673, in uvloop.loop.Loop._append_ready_handle

  File "uvloop/loop.pyx", line 705, in uvloop.loop.Loop._check_closed
  File "/home/ccl/anaconda3/envs/rrfedops/lib/python3.9/threading.py", line 1060, in join
RuntimeError: Event loop is closed
self._wait_for_tstate_lock()
During handling of the above exception, another exception occurred:


Traceback (most recent call last):
  File "/home/ccl/anaconda3/envs/rrfedops/lib/python3.9/threading.py", line 1080, in _wait_for_tstate_lock
  File "/home/ccl/anaconda3/envs/rrfedops/lib/python3.9/threading.py", line 980, in _bootstrap_inner
    if lock.acquire(block, timeout):
self.run()KeyboardInterrupt
:   File "/home/ccl/anaconda3/envs/rrfedops/lib/python3.9/threading.py", line 917, in run

self._target(*self._args, **self._kwargs)
  File "uvloop/loop.pyx", line 3256, in uvloop.loop.Loop._do_shutdown
  File "uvloop/loop.pyx", line 1290, in uvloop.loop.Loop.call_soon_threadsafe
  File "uvloop/loop.pyx", line 673, in uvloop.loop.Loop._append_ready_handle
  File "uvloop/loop.pyx", line 705, in uvloop.loop.Loop._check_closed
RuntimeError: Event loop is closed
