2025-09-29 17:25:08,422 INFO    MainThread:609037 [wandb_setup.py:_flush():67] Current SDK version is 0.19.9
2025-09-29 17:25:08,422 INFO    MainThread:609037 [wandb_setup.py:_flush():67] Configure stats pid to 609037
2025-09-29 17:25:08,423 INFO    MainThread:609037 [wandb_setup.py:_flush():67] Loading settings from /home/ccl/.config/wandb/settings
2025-09-29 17:25:08,423 INFO    MainThread:609037 [wandb_setup.py:_flush():67] Loading settings from /home/ccl/Desktop/RR/FedOps2/fedopstest/wandb/settings
2025-09-29 17:25:08,423 INFO    MainThread:609037 [wandb_setup.py:_flush():67] Loading settings from environment variables
2025-09-29 17:25:08,423 INFO    MainThread:609037 [wandb_init.py:setup_run_log_directory():662] Logging user logs to /home/ccl/Desktop/RR/FedOps2/fedopstest/wandb/run-20250929_172508-qh9c5vio/logs/debug.log
2025-09-29 17:25:08,423 INFO    MainThread:609037 [wandb_init.py:setup_run_log_directory():663] Logging internal logs to /home/ccl/Desktop/RR/FedOps2/fedopstest/wandb/run-20250929_172508-qh9c5vio/logs/debug-internal.log
2025-09-29 17:25:08,423 INFO    MainThread:609037 [wandb_init.py:init():781] calling init triggers
2025-09-29 17:25:08,423 INFO    MainThread:609037 [wandb_init.py:init():786] wandb.init called with sweep_config: {}
config: {'learning_rate': 0, 'optimizer': '', 'dataset': '', 'model_architecture': '', 'batch_size': 0, 'epochs': 0, 'num_rounds': 0, '_wandb': {}}
2025-09-29 17:25:08,423 INFO    MainThread:609037 [wandb_init.py:init():809] starting backend
2025-09-29 17:25:08,423 INFO    MainThread:609037 [wandb_init.py:init():813] sending inform_init request
2025-09-29 17:25:08,461 INFO    MainThread:609037 [backend.py:_multiprocessing_setup():101] multiprocessing start_methods=fork,spawn,forkserver, using: spawn
2025-09-29 17:25:08,462 INFO    MainThread:609037 [wandb_init.py:init():823] backend started and connected
2025-09-29 17:25:08,469 INFO    MainThread:609037 [wandb_init.py:init():915] updated telemetry
2025-09-29 17:25:08,499 INFO    MainThread:609037 [wandb_init.py:init():939] communicating run to backend with 90.0 second timeout
2025-09-29 17:25:09,358 INFO    MainThread:609037 [wandb_init.py:init():1014] starting run threads in backend
2025-09-29 17:25:09,541 INFO    MainThread:609037 [wandb_run.py:_console_start():2454] atexit reg
2025-09-29 17:25:09,541 INFO    MainThread:609037 [wandb_run.py:_redirect():2306] redirect: wrap_raw
2025-09-29 17:25:09,541 INFO    MainThread:609037 [wandb_run.py:_redirect():2371] Wrapping output streams.
2025-09-29 17:25:09,541 INFO    MainThread:609037 [wandb_run.py:_redirect():2394] Redirects installed.
2025-09-29 17:25:09,543 INFO    MainThread:609037 [wandb_init.py:init():1056] run started, returning control to user process
2025-09-29 17:54:00,569 INFO    MsgRouterThr:609037 [mailbox.py:close():129] [no run ID] Closing mailbox, abandoning 1 handles.
2025-09-29 17:54:00,985 ERROR   MainThread:609037 [redirect.py:_on_write():661] [no run ID] error in stderr callback
Traceback (most recent call last):
  File "/home/ccl/anaconda3/envs/rrfedops/lib/python3.9/site-packages/wandb/sdk/lib/redirect.py", line 659, in _on_write
    cb(written_data)
  File "/home/ccl/anaconda3/envs/rrfedops/lib/python3.9/site-packages/wandb/sdk/wandb_run.py", line 2381, in <lambda>
    lambda data: self._console_raw_callback("stderr", data),
  File "/home/ccl/anaconda3/envs/rrfedops/lib/python3.9/site-packages/wandb/sdk/wandb_run.py", line 387, in wrapper
    return func(self, *args, **kwargs)
  File "/home/ccl/anaconda3/envs/rrfedops/lib/python3.9/site-packages/wandb/sdk/wandb_run.py", line 435, in wrapper_fn
    return func(self, *args, **kwargs)
  File "/home/ccl/anaconda3/envs/rrfedops/lib/python3.9/site-packages/wandb/sdk/wandb_run.py", line 1518, in _console_raw_callback
    self._backend.interface.publish_output_raw(name, data)
  File "/home/ccl/anaconda3/envs/rrfedops/lib/python3.9/site-packages/wandb/sdk/interface/interface.py", line 761, in publish_output_raw
    self._publish_output_raw(o)
  File "/home/ccl/anaconda3/envs/rrfedops/lib/python3.9/site-packages/wandb/sdk/interface/interface_shared.py", line 38, in _publish_output_raw
    self._publish(rec)
  File "/home/ccl/anaconda3/envs/rrfedops/lib/python3.9/site-packages/wandb/sdk/interface/interface_sock.py", line 39, in _publish
    self._sock_client.send_record_publish(record)
  File "/home/ccl/anaconda3/envs/rrfedops/lib/python3.9/site-packages/wandb/sdk/lib/sock_client.py", line 174, in send_record_publish
    self.send_server_request(server_req)
  File "/home/ccl/anaconda3/envs/rrfedops/lib/python3.9/site-packages/wandb/sdk/lib/sock_client.py", line 154, in send_server_request
    self._send_message(msg)
  File "/home/ccl/anaconda3/envs/rrfedops/lib/python3.9/site-packages/wandb/sdk/lib/sock_client.py", line 151, in _send_message
    self._sendall_with_error_handle(header + data)
  File "/home/ccl/anaconda3/envs/rrfedops/lib/python3.9/site-packages/wandb/sdk/lib/sock_client.py", line 130, in _sendall_with_error_handle
    sent = self._sock.send(data)
BrokenPipeError: [Errno 32] Broken pipe
2025-09-29 17:54:00,999 ERROR   MainThread:609037 [redirect.py:_on_write():661] [no run ID] error in stderr callback
Traceback (most recent call last):
  File "/home/ccl/anaconda3/envs/rrfedops/lib/python3.9/site-packages/wandb/sdk/lib/redirect.py", line 659, in _on_write
    cb(written_data)
  File "/home/ccl/anaconda3/envs/rrfedops/lib/python3.9/site-packages/wandb/sdk/wandb_run.py", line 2381, in <lambda>
    lambda data: self._console_raw_callback("stderr", data),
  File "/home/ccl/anaconda3/envs/rrfedops/lib/python3.9/site-packages/wandb/sdk/wandb_run.py", line 387, in wrapper
    return func(self, *args, **kwargs)
  File "/home/ccl/anaconda3/envs/rrfedops/lib/python3.9/site-packages/wandb/sdk/wandb_run.py", line 435, in wrapper_fn
    return func(self, *args, **kwargs)
  File "/home/ccl/anaconda3/envs/rrfedops/lib/python3.9/site-packages/wandb/sdk/wandb_run.py", line 1518, in _console_raw_callback
    self._backend.interface.publish_output_raw(name, data)
  File "/home/ccl/anaconda3/envs/rrfedops/lib/python3.9/site-packages/wandb/sdk/interface/interface.py", line 761, in publish_output_raw
    self._publish_output_raw(o)
  File "/home/ccl/anaconda3/envs/rrfedops/lib/python3.9/site-packages/wandb/sdk/interface/interface_shared.py", line 38, in _publish_output_raw
    self._publish(rec)
  File "/home/ccl/anaconda3/envs/rrfedops/lib/python3.9/site-packages/wandb/sdk/interface/interface_sock.py", line 39, in _publish
    self._sock_client.send_record_publish(record)
  File "/home/ccl/anaconda3/envs/rrfedops/lib/python3.9/site-packages/wandb/sdk/lib/sock_client.py", line 174, in send_record_publish
    self.send_server_request(server_req)
  File "/home/ccl/anaconda3/envs/rrfedops/lib/python3.9/site-packages/wandb/sdk/lib/sock_client.py", line 154, in send_server_request
    self._send_message(msg)
  File "/home/ccl/anaconda3/envs/rrfedops/lib/python3.9/site-packages/wandb/sdk/lib/sock_client.py", line 151, in _send_message
    self._sendall_with_error_handle(header + data)
  File "/home/ccl/anaconda3/envs/rrfedops/lib/python3.9/site-packages/wandb/sdk/lib/sock_client.py", line 130, in _sendall_with_error_handle
    sent = self._sock.send(data)
BrokenPipeError: [Errno 32] Broken pipe
2025-09-29 17:54:01,001 ERROR   MainThread:609037 [redirect.py:_on_write():661] [no run ID] error in stderr callback
Traceback (most recent call last):
  File "/home/ccl/anaconda3/envs/rrfedops/lib/python3.9/site-packages/wandb/sdk/lib/redirect.py", line 659, in _on_write
    cb(written_data)
  File "/home/ccl/anaconda3/envs/rrfedops/lib/python3.9/site-packages/wandb/sdk/wandb_run.py", line 2381, in <lambda>
    lambda data: self._console_raw_callback("stderr", data),
  File "/home/ccl/anaconda3/envs/rrfedops/lib/python3.9/site-packages/wandb/sdk/wandb_run.py", line 387, in wrapper
    return func(self, *args, **kwargs)
  File "/home/ccl/anaconda3/envs/rrfedops/lib/python3.9/site-packages/wandb/sdk/wandb_run.py", line 435, in wrapper_fn
    return func(self, *args, **kwargs)
  File "/home/ccl/anaconda3/envs/rrfedops/lib/python3.9/site-packages/wandb/sdk/wandb_run.py", line 1518, in _console_raw_callback
    self._backend.interface.publish_output_raw(name, data)
  File "/home/ccl/anaconda3/envs/rrfedops/lib/python3.9/site-packages/wandb/sdk/interface/interface.py", line 761, in publish_output_raw
    self._publish_output_raw(o)
  File "/home/ccl/anaconda3/envs/rrfedops/lib/python3.9/site-packages/wandb/sdk/interface/interface_shared.py", line 38, in _publish_output_raw
    self._publish(rec)
  File "/home/ccl/anaconda3/envs/rrfedops/lib/python3.9/site-packages/wandb/sdk/interface/interface_sock.py", line 39, in _publish
    self._sock_client.send_record_publish(record)
  File "/home/ccl/anaconda3/envs/rrfedops/lib/python3.9/site-packages/wandb/sdk/lib/sock_client.py", line 174, in send_record_publish
    self.send_server_request(server_req)
  File "/home/ccl/anaconda3/envs/rrfedops/lib/python3.9/site-packages/wandb/sdk/lib/sock_client.py", line 154, in send_server_request
    self._send_message(msg)
  File "/home/ccl/anaconda3/envs/rrfedops/lib/python3.9/site-packages/wandb/sdk/lib/sock_client.py", line 151, in _send_message
    self._sendall_with_error_handle(header + data)
  File "/home/ccl/anaconda3/envs/rrfedops/lib/python3.9/site-packages/wandb/sdk/lib/sock_client.py", line 130, in _sendall_with_error_handle
    sent = self._sock.send(data)
BrokenPipeError: [Errno 32] Broken pipe
2025-09-29 17:54:01,002 ERROR   MainThread:609037 [redirect.py:_on_write():661] [no run ID] error in stderr callback
Traceback (most recent call last):
  File "/home/ccl/anaconda3/envs/rrfedops/lib/python3.9/site-packages/wandb/sdk/lib/redirect.py", line 659, in _on_write
    cb(written_data)
  File "/home/ccl/anaconda3/envs/rrfedops/lib/python3.9/site-packages/wandb/sdk/wandb_run.py", line 2381, in <lambda>
    lambda data: self._console_raw_callback("stderr", data),
  File "/home/ccl/anaconda3/envs/rrfedops/lib/python3.9/site-packages/wandb/sdk/wandb_run.py", line 387, in wrapper
    return func(self, *args, **kwargs)
  File "/home/ccl/anaconda3/envs/rrfedops/lib/python3.9/site-packages/wandb/sdk/wandb_run.py", line 435, in wrapper_fn
    return func(self, *args, **kwargs)
  File "/home/ccl/anaconda3/envs/rrfedops/lib/python3.9/site-packages/wandb/sdk/wandb_run.py", line 1518, in _console_raw_callback
    self._backend.interface.publish_output_raw(name, data)
  File "/home/ccl/anaconda3/envs/rrfedops/lib/python3.9/site-packages/wandb/sdk/interface/interface.py", line 761, in publish_output_raw
    self._publish_output_raw(o)
  File "/home/ccl/anaconda3/envs/rrfedops/lib/python3.9/site-packages/wandb/sdk/interface/interface_shared.py", line 38, in _publish_output_raw
    self._publish(rec)
  File "/home/ccl/anaconda3/envs/rrfedops/lib/python3.9/site-packages/wandb/sdk/interface/interface_sock.py", line 39, in _publish
    self._sock_client.send_record_publish(record)
  File "/home/ccl/anaconda3/envs/rrfedops/lib/python3.9/site-packages/wandb/sdk/lib/sock_client.py", line 174, in send_record_publish
    self.send_server_request(server_req)
  File "/home/ccl/anaconda3/envs/rrfedops/lib/python3.9/site-packages/wandb/sdk/lib/sock_client.py", line 154, in send_server_request
    self._send_message(msg)
  File "/home/ccl/anaconda3/envs/rrfedops/lib/python3.9/site-packages/wandb/sdk/lib/sock_client.py", line 151, in _send_message
    self._sendall_with_error_handle(header + data)
  File "/home/ccl/anaconda3/envs/rrfedops/lib/python3.9/site-packages/wandb/sdk/lib/sock_client.py", line 130, in _sendall_with_error_handle
    sent = self._sock.send(data)
BrokenPipeError: [Errno 32] Broken pipe
2025-09-29 17:54:01,002 ERROR   MainThread:609037 [redirect.py:_on_write():661] [no run ID] error in stderr callback
Traceback (most recent call last):
  File "/home/ccl/anaconda3/envs/rrfedops/lib/python3.9/site-packages/wandb/sdk/lib/redirect.py", line 659, in _on_write
    cb(written_data)
  File "/home/ccl/anaconda3/envs/rrfedops/lib/python3.9/site-packages/wandb/sdk/wandb_run.py", line 2381, in <lambda>
    lambda data: self._console_raw_callback("stderr", data),
  File "/home/ccl/anaconda3/envs/rrfedops/lib/python3.9/site-packages/wandb/sdk/wandb_run.py", line 387, in wrapper
    return func(self, *args, **kwargs)
  File "/home/ccl/anaconda3/envs/rrfedops/lib/python3.9/site-packages/wandb/sdk/wandb_run.py", line 435, in wrapper_fn
    return func(self, *args, **kwargs)
  File "/home/ccl/anaconda3/envs/rrfedops/lib/python3.9/site-packages/wandb/sdk/wandb_run.py", line 1518, in _console_raw_callback
    self._backend.interface.publish_output_raw(name, data)
  File "/home/ccl/anaconda3/envs/rrfedops/lib/python3.9/site-packages/wandb/sdk/interface/interface.py", line 761, in publish_output_raw
    self._publish_output_raw(o)
  File "/home/ccl/anaconda3/envs/rrfedops/lib/python3.9/site-packages/wandb/sdk/interface/interface_shared.py", line 38, in _publish_output_raw
    self._publish(rec)
  File "/home/ccl/anaconda3/envs/rrfedops/lib/python3.9/site-packages/wandb/sdk/interface/interface_sock.py", line 39, in _publish
    self._sock_client.send_record_publish(record)
  File "/home/ccl/anaconda3/envs/rrfedops/lib/python3.9/site-packages/wandb/sdk/lib/sock_client.py", line 174, in send_record_publish
    self.send_server_request(server_req)
  File "/home/ccl/anaconda3/envs/rrfedops/lib/python3.9/site-packages/wandb/sdk/lib/sock_client.py", line 154, in send_server_request
    self._send_message(msg)
  File "/home/ccl/anaconda3/envs/rrfedops/lib/python3.9/site-packages/wandb/sdk/lib/sock_client.py", line 151, in _send_message
    self._sendall_with_error_handle(header + data)
  File "/home/ccl/anaconda3/envs/rrfedops/lib/python3.9/site-packages/wandb/sdk/lib/sock_client.py", line 130, in _sendall_with_error_handle
    sent = self._sock.send(data)
BrokenPipeError: [Errno 32] Broken pipe
2025-09-29 17:54:01,003 ERROR   MainThread:609037 [redirect.py:_on_write():661] [no run ID] error in stderr callback
Traceback (most recent call last):
  File "/home/ccl/anaconda3/envs/rrfedops/lib/python3.9/site-packages/wandb/sdk/lib/redirect.py", line 659, in _on_write
    cb(written_data)
  File "/home/ccl/anaconda3/envs/rrfedops/lib/python3.9/site-packages/wandb/sdk/wandb_run.py", line 2381, in <lambda>
    lambda data: self._console_raw_callback("stderr", data),
  File "/home/ccl/anaconda3/envs/rrfedops/lib/python3.9/site-packages/wandb/sdk/wandb_run.py", line 387, in wrapper
    return func(self, *args, **kwargs)
  File "/home/ccl/anaconda3/envs/rrfedops/lib/python3.9/site-packages/wandb/sdk/wandb_run.py", line 435, in wrapper_fn
    return func(self, *args, **kwargs)
  File "/home/ccl/anaconda3/envs/rrfedops/lib/python3.9/site-packages/wandb/sdk/wandb_run.py", line 1518, in _console_raw_callback
    self._backend.interface.publish_output_raw(name, data)
  File "/home/ccl/anaconda3/envs/rrfedops/lib/python3.9/site-packages/wandb/sdk/interface/interface.py", line 761, in publish_output_raw
    self._publish_output_raw(o)
  File "/home/ccl/anaconda3/envs/rrfedops/lib/python3.9/site-packages/wandb/sdk/interface/interface_shared.py", line 38, in _publish_output_raw
    self._publish(rec)
  File "/home/ccl/anaconda3/envs/rrfedops/lib/python3.9/site-packages/wandb/sdk/interface/interface_sock.py", line 39, in _publish
    self._sock_client.send_record_publish(record)
  File "/home/ccl/anaconda3/envs/rrfedops/lib/python3.9/site-packages/wandb/sdk/lib/sock_client.py", line 174, in send_record_publish
    self.send_server_request(server_req)
  File "/home/ccl/anaconda3/envs/rrfedops/lib/python3.9/site-packages/wandb/sdk/lib/sock_client.py", line 154, in send_server_request
    self._send_message(msg)
  File "/home/ccl/anaconda3/envs/rrfedops/lib/python3.9/site-packages/wandb/sdk/lib/sock_client.py", line 151, in _send_message
    self._sendall_with_error_handle(header + data)
  File "/home/ccl/anaconda3/envs/rrfedops/lib/python3.9/site-packages/wandb/sdk/lib/sock_client.py", line 130, in _sendall_with_error_handle
    sent = self._sock.send(data)
BrokenPipeError: [Errno 32] Broken pipe
2025-09-29 17:54:01,004 ERROR   MainThread:609037 [redirect.py:_on_write():661] [no run ID] error in stderr callback
Traceback (most recent call last):
  File "/home/ccl/anaconda3/envs/rrfedops/lib/python3.9/site-packages/wandb/sdk/lib/redirect.py", line 659, in _on_write
    cb(written_data)
  File "/home/ccl/anaconda3/envs/rrfedops/lib/python3.9/site-packages/wandb/sdk/wandb_run.py", line 2381, in <lambda>
    lambda data: self._console_raw_callback("stderr", data),
  File "/home/ccl/anaconda3/envs/rrfedops/lib/python3.9/site-packages/wandb/sdk/wandb_run.py", line 387, in wrapper
    return func(self, *args, **kwargs)
  File "/home/ccl/anaconda3/envs/rrfedops/lib/python3.9/site-packages/wandb/sdk/wandb_run.py", line 435, in wrapper_fn
    return func(self, *args, **kwargs)
  File "/home/ccl/anaconda3/envs/rrfedops/lib/python3.9/site-packages/wandb/sdk/wandb_run.py", line 1518, in _console_raw_callback
    self._backend.interface.publish_output_raw(name, data)
  File "/home/ccl/anaconda3/envs/rrfedops/lib/python3.9/site-packages/wandb/sdk/interface/interface.py", line 761, in publish_output_raw
    self._publish_output_raw(o)
  File "/home/ccl/anaconda3/envs/rrfedops/lib/python3.9/site-packages/wandb/sdk/interface/interface_shared.py", line 38, in _publish_output_raw
    self._publish(rec)
  File "/home/ccl/anaconda3/envs/rrfedops/lib/python3.9/site-packages/wandb/sdk/interface/interface_sock.py", line 39, in _publish
    self._sock_client.send_record_publish(record)
  File "/home/ccl/anaconda3/envs/rrfedops/lib/python3.9/site-packages/wandb/sdk/lib/sock_client.py", line 174, in send_record_publish
    self.send_server_request(server_req)
  File "/home/ccl/anaconda3/envs/rrfedops/lib/python3.9/site-packages/wandb/sdk/lib/sock_client.py", line 154, in send_server_request
    self._send_message(msg)
  File "/home/ccl/anaconda3/envs/rrfedops/lib/python3.9/site-packages/wandb/sdk/lib/sock_client.py", line 151, in _send_message
    self._sendall_with_error_handle(header + data)
  File "/home/ccl/anaconda3/envs/rrfedops/lib/python3.9/site-packages/wandb/sdk/lib/sock_client.py", line 130, in _sendall_with_error_handle
    sent = self._sock.send(data)
BrokenPipeError: [Errno 32] Broken pipe
2025-09-29 17:54:01,005 ERROR   MainThread:609037 [redirect.py:_on_write():661] [no run ID] error in stderr callback
Traceback (most recent call last):
  File "/home/ccl/anaconda3/envs/rrfedops/lib/python3.9/site-packages/wandb/sdk/lib/redirect.py", line 659, in _on_write
    cb(written_data)
  File "/home/ccl/anaconda3/envs/rrfedops/lib/python3.9/site-packages/wandb/sdk/wandb_run.py", line 2381, in <lambda>
    lambda data: self._console_raw_callback("stderr", data),
  File "/home/ccl/anaconda3/envs/rrfedops/lib/python3.9/site-packages/wandb/sdk/wandb_run.py", line 387, in wrapper
    return func(self, *args, **kwargs)
  File "/home/ccl/anaconda3/envs/rrfedops/lib/python3.9/site-packages/wandb/sdk/wandb_run.py", line 435, in wrapper_fn
    return func(self, *args, **kwargs)
  File "/home/ccl/anaconda3/envs/rrfedops/lib/python3.9/site-packages/wandb/sdk/wandb_run.py", line 1518, in _console_raw_callback
    self._backend.interface.publish_output_raw(name, data)
  File "/home/ccl/anaconda3/envs/rrfedops/lib/python3.9/site-packages/wandb/sdk/interface/interface.py", line 761, in publish_output_raw
    self._publish_output_raw(o)
  File "/home/ccl/anaconda3/envs/rrfedops/lib/python3.9/site-packages/wandb/sdk/interface/interface_shared.py", line 38, in _publish_output_raw
    self._publish(rec)
  File "/home/ccl/anaconda3/envs/rrfedops/lib/python3.9/site-packages/wandb/sdk/interface/interface_sock.py", line 39, in _publish
    self._sock_client.send_record_publish(record)
  File "/home/ccl/anaconda3/envs/rrfedops/lib/python3.9/site-packages/wandb/sdk/lib/sock_client.py", line 174, in send_record_publish
    self.send_server_request(server_req)
  File "/home/ccl/anaconda3/envs/rrfedops/lib/python3.9/site-packages/wandb/sdk/lib/sock_client.py", line 154, in send_server_request
    self._send_message(msg)
  File "/home/ccl/anaconda3/envs/rrfedops/lib/python3.9/site-packages/wandb/sdk/lib/sock_client.py", line 151, in _send_message
    self._sendall_with_error_handle(header + data)
  File "/home/ccl/anaconda3/envs/rrfedops/lib/python3.9/site-packages/wandb/sdk/lib/sock_client.py", line 130, in _sendall_with_error_handle
    sent = self._sock.send(data)
BrokenPipeError: [Errno 32] Broken pipe
2025-09-29 17:54:01,006 ERROR   MainThread:609037 [redirect.py:_on_write():661] [no run ID] error in stderr callback
Traceback (most recent call last):
  File "/home/ccl/anaconda3/envs/rrfedops/lib/python3.9/site-packages/wandb/sdk/lib/redirect.py", line 659, in _on_write
    cb(written_data)
  File "/home/ccl/anaconda3/envs/rrfedops/lib/python3.9/site-packages/wandb/sdk/wandb_run.py", line 2381, in <lambda>
    lambda data: self._console_raw_callback("stderr", data),
  File "/home/ccl/anaconda3/envs/rrfedops/lib/python3.9/site-packages/wandb/sdk/wandb_run.py", line 387, in wrapper
    return func(self, *args, **kwargs)
  File "/home/ccl/anaconda3/envs/rrfedops/lib/python3.9/site-packages/wandb/sdk/wandb_run.py", line 435, in wrapper_fn
    return func(self, *args, **kwargs)
  File "/home/ccl/anaconda3/envs/rrfedops/lib/python3.9/site-packages/wandb/sdk/wandb_run.py", line 1518, in _console_raw_callback
    self._backend.interface.publish_output_raw(name, data)
  File "/home/ccl/anaconda3/envs/rrfedops/lib/python3.9/site-packages/wandb/sdk/interface/interface.py", line 761, in publish_output_raw
    self._publish_output_raw(o)
  File "/home/ccl/anaconda3/envs/rrfedops/lib/python3.9/site-packages/wandb/sdk/interface/interface_shared.py", line 38, in _publish_output_raw
    self._publish(rec)
  File "/home/ccl/anaconda3/envs/rrfedops/lib/python3.9/site-packages/wandb/sdk/interface/interface_sock.py", line 39, in _publish
    self._sock_client.send_record_publish(record)
  File "/home/ccl/anaconda3/envs/rrfedops/lib/python3.9/site-packages/wandb/sdk/lib/sock_client.py", line 174, in send_record_publish
    self.send_server_request(server_req)
  File "/home/ccl/anaconda3/envs/rrfedops/lib/python3.9/site-packages/wandb/sdk/lib/sock_client.py", line 154, in send_server_request
    self._send_message(msg)
  File "/home/ccl/anaconda3/envs/rrfedops/lib/python3.9/site-packages/wandb/sdk/lib/sock_client.py", line 151, in _send_message
    self._sendall_with_error_handle(header + data)
  File "/home/ccl/anaconda3/envs/rrfedops/lib/python3.9/site-packages/wandb/sdk/lib/sock_client.py", line 130, in _sendall_with_error_handle
    sent = self._sock.send(data)
BrokenPipeError: [Errno 32] Broken pipe
2025-09-29 17:54:01,006 ERROR   MainThread:609037 [redirect.py:_on_write():661] [no run ID] error in stderr callback
Traceback (most recent call last):
  File "/home/ccl/anaconda3/envs/rrfedops/lib/python3.9/site-packages/wandb/sdk/lib/redirect.py", line 659, in _on_write
    cb(written_data)
  File "/home/ccl/anaconda3/envs/rrfedops/lib/python3.9/site-packages/wandb/sdk/wandb_run.py", line 2381, in <lambda>
    lambda data: self._console_raw_callback("stderr", data),
  File "/home/ccl/anaconda3/envs/rrfedops/lib/python3.9/site-packages/wandb/sdk/wandb_run.py", line 387, in wrapper
    return func(self, *args, **kwargs)
  File "/home/ccl/anaconda3/envs/rrfedops/lib/python3.9/site-packages/wandb/sdk/wandb_run.py", line 435, in wrapper_fn
    return func(self, *args, **kwargs)
  File "/home/ccl/anaconda3/envs/rrfedops/lib/python3.9/site-packages/wandb/sdk/wandb_run.py", line 1518, in _console_raw_callback
    self._backend.interface.publish_output_raw(name, data)
  File "/home/ccl/anaconda3/envs/rrfedops/lib/python3.9/site-packages/wandb/sdk/interface/interface.py", line 761, in publish_output_raw
    self._publish_output_raw(o)
  File "/home/ccl/anaconda3/envs/rrfedops/lib/python3.9/site-packages/wandb/sdk/interface/interface_shared.py", line 38, in _publish_output_raw
    self._publish(rec)
  File "/home/ccl/anaconda3/envs/rrfedops/lib/python3.9/site-packages/wandb/sdk/interface/interface_sock.py", line 39, in _publish
    self._sock_client.send_record_publish(record)
  File "/home/ccl/anaconda3/envs/rrfedops/lib/python3.9/site-packages/wandb/sdk/lib/sock_client.py", line 174, in send_record_publish
    self.send_server_request(server_req)
  File "/home/ccl/anaconda3/envs/rrfedops/lib/python3.9/site-packages/wandb/sdk/lib/sock_client.py", line 154, in send_server_request
    self._send_message(msg)
  File "/home/ccl/anaconda3/envs/rrfedops/lib/python3.9/site-packages/wandb/sdk/lib/sock_client.py", line 151, in _send_message
    self._sendall_with_error_handle(header + data)
  File "/home/ccl/anaconda3/envs/rrfedops/lib/python3.9/site-packages/wandb/sdk/lib/sock_client.py", line 130, in _sendall_with_error_handle
    sent = self._sock.send(data)
BrokenPipeError: [Errno 32] Broken pipe
2025-09-29 17:54:01,008 ERROR   MainThread:609037 [redirect.py:_on_write():661] [no run ID] error in stderr callback
Traceback (most recent call last):
  File "/home/ccl/anaconda3/envs/rrfedops/lib/python3.9/site-packages/wandb/sdk/lib/redirect.py", line 659, in _on_write
    cb(written_data)
  File "/home/ccl/anaconda3/envs/rrfedops/lib/python3.9/site-packages/wandb/sdk/wandb_run.py", line 2381, in <lambda>
    lambda data: self._console_raw_callback("stderr", data),
  File "/home/ccl/anaconda3/envs/rrfedops/lib/python3.9/site-packages/wandb/sdk/wandb_run.py", line 387, in wrapper
    return func(self, *args, **kwargs)
  File "/home/ccl/anaconda3/envs/rrfedops/lib/python3.9/site-packages/wandb/sdk/wandb_run.py", line 435, in wrapper_fn
    return func(self, *args, **kwargs)
  File "/home/ccl/anaconda3/envs/rrfedops/lib/python3.9/site-packages/wandb/sdk/wandb_run.py", line 1518, in _console_raw_callback
    self._backend.interface.publish_output_raw(name, data)
  File "/home/ccl/anaconda3/envs/rrfedops/lib/python3.9/site-packages/wandb/sdk/interface/interface.py", line 761, in publish_output_raw
    self._publish_output_raw(o)
  File "/home/ccl/anaconda3/envs/rrfedops/lib/python3.9/site-packages/wandb/sdk/interface/interface_shared.py", line 38, in _publish_output_raw
    self._publish(rec)
  File "/home/ccl/anaconda3/envs/rrfedops/lib/python3.9/site-packages/wandb/sdk/interface/interface_sock.py", line 39, in _publish
    self._sock_client.send_record_publish(record)
  File "/home/ccl/anaconda3/envs/rrfedops/lib/python3.9/site-packages/wandb/sdk/lib/sock_client.py", line 174, in send_record_publish
    self.send_server_request(server_req)
  File "/home/ccl/anaconda3/envs/rrfedops/lib/python3.9/site-packages/wandb/sdk/lib/sock_client.py", line 154, in send_server_request
    self._send_message(msg)
  File "/home/ccl/anaconda3/envs/rrfedops/lib/python3.9/site-packages/wandb/sdk/lib/sock_client.py", line 151, in _send_message
    self._sendall_with_error_handle(header + data)
  File "/home/ccl/anaconda3/envs/rrfedops/lib/python3.9/site-packages/wandb/sdk/lib/sock_client.py", line 130, in _sendall_with_error_handle
    sent = self._sock.send(data)
BrokenPipeError: [Errno 32] Broken pipe
2025-09-29 17:54:01,009 ERROR   MainThread:609037 [redirect.py:_on_write():661] [no run ID] error in stderr callback
Traceback (most recent call last):
  File "/home/ccl/anaconda3/envs/rrfedops/lib/python3.9/site-packages/wandb/sdk/lib/redirect.py", line 659, in _on_write
    cb(written_data)
  File "/home/ccl/anaconda3/envs/rrfedops/lib/python3.9/site-packages/wandb/sdk/wandb_run.py", line 2381, in <lambda>
    lambda data: self._console_raw_callback("stderr", data),
  File "/home/ccl/anaconda3/envs/rrfedops/lib/python3.9/site-packages/wandb/sdk/wandb_run.py", line 387, in wrapper
    return func(self, *args, **kwargs)
  File "/home/ccl/anaconda3/envs/rrfedops/lib/python3.9/site-packages/wandb/sdk/wandb_run.py", line 435, in wrapper_fn
    return func(self, *args, **kwargs)
  File "/home/ccl/anaconda3/envs/rrfedops/lib/python3.9/site-packages/wandb/sdk/wandb_run.py", line 1518, in _console_raw_callback
    self._backend.interface.publish_output_raw(name, data)
  File "/home/ccl/anaconda3/envs/rrfedops/lib/python3.9/site-packages/wandb/sdk/interface/interface.py", line 761, in publish_output_raw
    self._publish_output_raw(o)
  File "/home/ccl/anaconda3/envs/rrfedops/lib/python3.9/site-packages/wandb/sdk/interface/interface_shared.py", line 38, in _publish_output_raw
    self._publish(rec)
  File "/home/ccl/anaconda3/envs/rrfedops/lib/python3.9/site-packages/wandb/sdk/interface/interface_sock.py", line 39, in _publish
    self._sock_client.send_record_publish(record)
  File "/home/ccl/anaconda3/envs/rrfedops/lib/python3.9/site-packages/wandb/sdk/lib/sock_client.py", line 174, in send_record_publish
    self.send_server_request(server_req)
  File "/home/ccl/anaconda3/envs/rrfedops/lib/python3.9/site-packages/wandb/sdk/lib/sock_client.py", line 154, in send_server_request
    self._send_message(msg)
  File "/home/ccl/anaconda3/envs/rrfedops/lib/python3.9/site-packages/wandb/sdk/lib/sock_client.py", line 151, in _send_message
    self._sendall_with_error_handle(header + data)
  File "/home/ccl/anaconda3/envs/rrfedops/lib/python3.9/site-packages/wandb/sdk/lib/sock_client.py", line 130, in _sendall_with_error_handle
    sent = self._sock.send(data)
BrokenPipeError: [Errno 32] Broken pipe
2025-09-29 17:54:01,009 ERROR   MainThread:609037 [redirect.py:_on_write():661] [no run ID] error in stderr callback
Traceback (most recent call last):
  File "/home/ccl/anaconda3/envs/rrfedops/lib/python3.9/site-packages/wandb/sdk/lib/redirect.py", line 659, in _on_write
    cb(written_data)
  File "/home/ccl/anaconda3/envs/rrfedops/lib/python3.9/site-packages/wandb/sdk/wandb_run.py", line 2381, in <lambda>
    lambda data: self._console_raw_callback("stderr", data),
  File "/home/ccl/anaconda3/envs/rrfedops/lib/python3.9/site-packages/wandb/sdk/wandb_run.py", line 387, in wrapper
    return func(self, *args, **kwargs)
  File "/home/ccl/anaconda3/envs/rrfedops/lib/python3.9/site-packages/wandb/sdk/wandb_run.py", line 435, in wrapper_fn
    return func(self, *args, **kwargs)
  File "/home/ccl/anaconda3/envs/rrfedops/lib/python3.9/site-packages/wandb/sdk/wandb_run.py", line 1518, in _console_raw_callback
    self._backend.interface.publish_output_raw(name, data)
  File "/home/ccl/anaconda3/envs/rrfedops/lib/python3.9/site-packages/wandb/sdk/interface/interface.py", line 761, in publish_output_raw
    self._publish_output_raw(o)
  File "/home/ccl/anaconda3/envs/rrfedops/lib/python3.9/site-packages/wandb/sdk/interface/interface_shared.py", line 38, in _publish_output_raw
    self._publish(rec)
  File "/home/ccl/anaconda3/envs/rrfedops/lib/python3.9/site-packages/wandb/sdk/interface/interface_sock.py", line 39, in _publish
    self._sock_client.send_record_publish(record)
  File "/home/ccl/anaconda3/envs/rrfedops/lib/python3.9/site-packages/wandb/sdk/lib/sock_client.py", line 174, in send_record_publish
    self.send_server_request(server_req)
  File "/home/ccl/anaconda3/envs/rrfedops/lib/python3.9/site-packages/wandb/sdk/lib/sock_client.py", line 154, in send_server_request
    self._send_message(msg)
  File "/home/ccl/anaconda3/envs/rrfedops/lib/python3.9/site-packages/wandb/sdk/lib/sock_client.py", line 151, in _send_message
    self._sendall_with_error_handle(header + data)
  File "/home/ccl/anaconda3/envs/rrfedops/lib/python3.9/site-packages/wandb/sdk/lib/sock_client.py", line 130, in _sendall_with_error_handle
    sent = self._sock.send(data)
BrokenPipeError: [Errno 32] Broken pipe
2025-09-29 17:54:01,010 ERROR   MainThread:609037 [redirect.py:_on_write():661] [no run ID] error in stderr callback
Traceback (most recent call last):
  File "/home/ccl/anaconda3/envs/rrfedops/lib/python3.9/site-packages/wandb/sdk/lib/redirect.py", line 659, in _on_write
    cb(written_data)
  File "/home/ccl/anaconda3/envs/rrfedops/lib/python3.9/site-packages/wandb/sdk/wandb_run.py", line 2381, in <lambda>
    lambda data: self._console_raw_callback("stderr", data),
  File "/home/ccl/anaconda3/envs/rrfedops/lib/python3.9/site-packages/wandb/sdk/wandb_run.py", line 387, in wrapper
    return func(self, *args, **kwargs)
  File "/home/ccl/anaconda3/envs/rrfedops/lib/python3.9/site-packages/wandb/sdk/wandb_run.py", line 435, in wrapper_fn
    return func(self, *args, **kwargs)
  File "/home/ccl/anaconda3/envs/rrfedops/lib/python3.9/site-packages/wandb/sdk/wandb_run.py", line 1518, in _console_raw_callback
    self._backend.interface.publish_output_raw(name, data)
  File "/home/ccl/anaconda3/envs/rrfedops/lib/python3.9/site-packages/wandb/sdk/interface/interface.py", line 761, in publish_output_raw
    self._publish_output_raw(o)
  File "/home/ccl/anaconda3/envs/rrfedops/lib/python3.9/site-packages/wandb/sdk/interface/interface_shared.py", line 38, in _publish_output_raw
    self._publish(rec)
  File "/home/ccl/anaconda3/envs/rrfedops/lib/python3.9/site-packages/wandb/sdk/interface/interface_sock.py", line 39, in _publish
    self._sock_client.send_record_publish(record)
  File "/home/ccl/anaconda3/envs/rrfedops/lib/python3.9/site-packages/wandb/sdk/lib/sock_client.py", line 174, in send_record_publish
    self.send_server_request(server_req)
  File "/home/ccl/anaconda3/envs/rrfedops/lib/python3.9/site-packages/wandb/sdk/lib/sock_client.py", line 154, in send_server_request
    self._send_message(msg)
  File "/home/ccl/anaconda3/envs/rrfedops/lib/python3.9/site-packages/wandb/sdk/lib/sock_client.py", line 151, in _send_message
    self._sendall_with_error_handle(header + data)
  File "/home/ccl/anaconda3/envs/rrfedops/lib/python3.9/site-packages/wandb/sdk/lib/sock_client.py", line 130, in _sendall_with_error_handle
    sent = self._sock.send(data)
BrokenPipeError: [Errno 32] Broken pipe
2025-09-29 17:54:01,011 ERROR   MainThread:609037 [redirect.py:_on_write():661] [no run ID] error in stderr callback
Traceback (most recent call last):
  File "/home/ccl/anaconda3/envs/rrfedops/lib/python3.9/site-packages/wandb/sdk/lib/redirect.py", line 659, in _on_write
    cb(written_data)
  File "/home/ccl/anaconda3/envs/rrfedops/lib/python3.9/site-packages/wandb/sdk/wandb_run.py", line 2381, in <lambda>
    lambda data: self._console_raw_callback("stderr", data),
  File "/home/ccl/anaconda3/envs/rrfedops/lib/python3.9/site-packages/wandb/sdk/wandb_run.py", line 387, in wrapper
    return func(self, *args, **kwargs)
  File "/home/ccl/anaconda3/envs/rrfedops/lib/python3.9/site-packages/wandb/sdk/wandb_run.py", line 435, in wrapper_fn
    return func(self, *args, **kwargs)
  File "/home/ccl/anaconda3/envs/rrfedops/lib/python3.9/site-packages/wandb/sdk/wandb_run.py", line 1518, in _console_raw_callback
    self._backend.interface.publish_output_raw(name, data)
  File "/home/ccl/anaconda3/envs/rrfedops/lib/python3.9/site-packages/wandb/sdk/interface/interface.py", line 761, in publish_output_raw
    self._publish_output_raw(o)
  File "/home/ccl/anaconda3/envs/rrfedops/lib/python3.9/site-packages/wandb/sdk/interface/interface_shared.py", line 38, in _publish_output_raw
    self._publish(rec)
  File "/home/ccl/anaconda3/envs/rrfedops/lib/python3.9/site-packages/wandb/sdk/interface/interface_sock.py", line 39, in _publish
    self._sock_client.send_record_publish(record)
  File "/home/ccl/anaconda3/envs/rrfedops/lib/python3.9/site-packages/wandb/sdk/lib/sock_client.py", line 174, in send_record_publish
    self.send_server_request(server_req)
  File "/home/ccl/anaconda3/envs/rrfedops/lib/python3.9/site-packages/wandb/sdk/lib/sock_client.py", line 154, in send_server_request
    self._send_message(msg)
  File "/home/ccl/anaconda3/envs/rrfedops/lib/python3.9/site-packages/wandb/sdk/lib/sock_client.py", line 151, in _send_message
    self._sendall_with_error_handle(header + data)
  File "/home/ccl/anaconda3/envs/rrfedops/lib/python3.9/site-packages/wandb/sdk/lib/sock_client.py", line 130, in _sendall_with_error_handle
    sent = self._sock.send(data)
BrokenPipeError: [Errno 32] Broken pipe
2025-09-29 17:54:01,011 ERROR   MainThread:609037 [redirect.py:_on_write():661] [no run ID] error in stderr callback
Traceback (most recent call last):
  File "/home/ccl/anaconda3/envs/rrfedops/lib/python3.9/site-packages/wandb/sdk/lib/redirect.py", line 659, in _on_write
    cb(written_data)
  File "/home/ccl/anaconda3/envs/rrfedops/lib/python3.9/site-packages/wandb/sdk/wandb_run.py", line 2381, in <lambda>
    lambda data: self._console_raw_callback("stderr", data),
  File "/home/ccl/anaconda3/envs/rrfedops/lib/python3.9/site-packages/wandb/sdk/wandb_run.py", line 387, in wrapper
    return func(self, *args, **kwargs)
  File "/home/ccl/anaconda3/envs/rrfedops/lib/python3.9/site-packages/wandb/sdk/wandb_run.py", line 435, in wrapper_fn
    return func(self, *args, **kwargs)
  File "/home/ccl/anaconda3/envs/rrfedops/lib/python3.9/site-packages/wandb/sdk/wandb_run.py", line 1518, in _console_raw_callback
    self._backend.interface.publish_output_raw(name, data)
  File "/home/ccl/anaconda3/envs/rrfedops/lib/python3.9/site-packages/wandb/sdk/interface/interface.py", line 761, in publish_output_raw
    self._publish_output_raw(o)
  File "/home/ccl/anaconda3/envs/rrfedops/lib/python3.9/site-packages/wandb/sdk/interface/interface_shared.py", line 38, in _publish_output_raw
    self._publish(rec)
  File "/home/ccl/anaconda3/envs/rrfedops/lib/python3.9/site-packages/wandb/sdk/interface/interface_sock.py", line 39, in _publish
    self._sock_client.send_record_publish(record)
  File "/home/ccl/anaconda3/envs/rrfedops/lib/python3.9/site-packages/wandb/sdk/lib/sock_client.py", line 174, in send_record_publish
    self.send_server_request(server_req)
  File "/home/ccl/anaconda3/envs/rrfedops/lib/python3.9/site-packages/wandb/sdk/lib/sock_client.py", line 154, in send_server_request
    self._send_message(msg)
  File "/home/ccl/anaconda3/envs/rrfedops/lib/python3.9/site-packages/wandb/sdk/lib/sock_client.py", line 151, in _send_message
    self._sendall_with_error_handle(header + data)
  File "/home/ccl/anaconda3/envs/rrfedops/lib/python3.9/site-packages/wandb/sdk/lib/sock_client.py", line 130, in _sendall_with_error_handle
    sent = self._sock.send(data)
BrokenPipeError: [Errno 32] Broken pipe
